Running Move unit tests
[ PASS    ] 0x1::A::native_abort_good_right_code
[ FAIL    ] 0x1::A::native_abort_good_wrong_code
[ FAIL    ] 0x1::A::native_abort_unexpected_abort
0x1::A::native_abort_good_right_code
Output: Ok(ChangeSet { accounts: {} })
0x1::A::native_abort_good_wrong_code
Output: Ok(ChangeSet { accounts: {} })
0x1::A::native_abort_unexpected_abort
Output: Ok(ChangeSet { accounts: {} })

Test failures:

Failures in 0x1::A:

┌── native_abort_good_wrong_code ──────
│ error[E11001]: test failure
│    ┌─ native_abort.move:12:9
│    │
│ 11 │     fun native_abort_good_wrong_code() {
│    │         ---------------------------- In this function in 0x1::A
│ 12 │         vector::borrow(&vector::empty<u64>(), 1);
│    │         ^^^^^^^^^^^^^^^^^^^^^^^^^^^^^^^^^^^^^^^^ Test did not fail with the expected error. Expected test to error with a vector operation error with sub-status code 0 originating in the module 00000000000000000000000000000001::A but instead it errored with a vector operation error with sub-status code 1 originating in the module 00000000000000000000000000000001::A. Rooted here
│ 
│ 
└──────────────────


┌── native_abort_unexpected_abort ──────
│ error[E11001]: test failure
│   ┌─ native_abort.move:6:9
│   │
│ 5 │     fun native_abort_unexpected_abort() {
│   │         ----------------------------- In this function in 0x1::A
│ 6 │         vector::borrow(&vector::empty<u64>(), 1);
│   │         ^^^^^^^^^^^^^^^^^^^^^^^^^^^^^^^^^^^^^^^^ Test was not expected to fail but it errored with a vector operation error with sub-status code 1 originating in the module 00000000000000000000000000000001::A. Rooted here
│ 
│ 
└──────────────────

Test result: FAILED. Total tests: 3; passed: 1; failed: 2
